<?xml version="1.0" encoding="utf-8"?>

<!-- 10242024-alpha-1 -->

<robot
  name="GR1T2_remove_head">
  <link
    name="base_link">
    <inertial>
      <origin
        xyz="-0.0610430075537095 -0.000110267171091749 -0.00899136549001815"
        rpy="0 0 0" />
      <mass
        value="3.84978430634043" />
      <inertia
        ixx="0.00945478634676121"
        ixy="-1.54640994793173E-06"
        ixz="9.15609796908774E-05"
        iyy="0.00512313489716132"
        iyz="2.39477384137869E-06"
        izz="0.00905709380325077" />
    </inertial>
    <visual>
      <origin
        xyz="0 0 0"
        rpy="0 0 0" />
      <geometry>
        <mesh
          filename="../meshes/base_link.STL" />
      </geometry>
      <material
        name="">
        <color
          rgba="0.752941176470588 0.752941176470588 0.752941176470588 1" />
      </material>
    </visual>
    <collision>
      <origin
        xyz="0 0 0"
        rpy="0 0 0" />
      <geometry>
        <mesh
          filename="../meshes/base_link.STL" />
      </geometry>
    </collision>
  </link>
  <link
    name="left_thigh_roll_link">
    <inertial>
      <origin
        xyz="-0.0140831220695678 -3.43737770712414E-05 -0.000238426434277079"
        rpy="0 0 0" />
      <mass
        value="1507.18991792145" />
      <inertia
        ixx="0.879427028313038"
        ixy="0.000104710980284316"
        ixz="-0.000445179169088434"
        iyy="0.577803770876916"
        iyz="7.47413198384937E-05"
        izz="0.784819900051551" />
    </inertial>
    <visual>
      <origin
        xyz="0 0 0"
        rpy="0 0 0" />
      <geometry>
        <mesh
          filename="../meshes/left_thigh_roll_link.STL" />
      </geometry>
      <material
        name="">
        <color
          rgba="0.752941176470588 0.752941176470588 0.752941176470588 1" />
      </material>
    </visual>
    <collision>
      <origin
        xyz="0 0 0"
        rpy="0 0 0" />
      <geometry>
        <mesh
          filename="../meshes/left_thigh_roll_link.STL" />
      </geometry>
    </collision>
  </link>
  <joint
    name="left_hip_roll_joint"
    type="revolute">
    <origin
      xyz="-0.031635 0.105 -0.0276"
      rpy="0 0 0" />
    <parent
      link="base_link" />
    <child
      link="left_thigh_roll_link" />
    <axis
      xyz="1 0 0" />
    <limit
      lower="-0.09"
      upper="0.79"
      effort="48"
      velocity="12.15" />
  </joint>
  <link
    name="left_thigh_yaw_link">
    <inertial>
      <origin
        xyz="-0.000818084781117501 0.0303818537799241 -0.0865515215870815"
        rpy="0 0 0" />
      <mass
        value="2.94576368544194" />
      <inertia
        ixx="0.00546367941343903"
        ixy="5.5201164838595E-05"
        ixz="-9.89572682115933E-05"
        iyy="0.00832379493940564"
        iyz="-0.000476239791204946"
        izz="0.00427175618105044" />
    </inertial>
    <visual>
      <origin
        xyz="0 0 0"
        rpy="0 0 0" />
      <geometry>
        <mesh
          filename="../meshes/left_thigh_yaw_link.STL" />
      </geometry>
      <material
        name="">
        <color
          rgba="0.752941176470588 0.752941176470588 0.752941176470588 1" />
      </material>
    </visual>
    <collision>
      <origin
        xyz="0 0 0"
        rpy="0 0 0" />
      <geometry>
        <mesh
          filename="../meshes/left_thigh_yaw_link.STL" />
      </geometry>
    </collision>
  </link>
  <joint
    name="left_hip_yaw_joint"
    type="revolute">
    <origin
      xyz="0.033135 0 0.00075"
      rpy="0 0 0" />
    <parent
      link="left_thigh_roll_link" />
    <child
      link="left_thigh_yaw_link" />
    <axis
      xyz="0 0 1" />
    <limit
      lower="-0.7"
      upper="0.7"
      effort="66"
      velocity="16.76" />
  </joint>
  <link
    name="left_thigh_pitch_link">
    <inertial>
      <origin
        xyz="0.00217913553210536 -0.0286197089993597 -0.082879347872839"
        rpy="0 0 0" />
      <mass
        value="5.54803744509886" />
      <inertia
        ixx="0.0422878551072849"
        ixy="-7.61636501654725E-05"
        ixz="-0.000688563335705232"
        iyy="0.0493687573991481"
        iyz="-0.000622818432233612"
        izz="0.00802718397966057" />
    </inertial>
    <visual>
      <origin
        xyz="0 0 0"
        rpy="0 0 0" />
      <geometry>
        <mesh
          filename="../meshes/left_thigh_pitch_link.STL" />
      </geometry>
      <material
        name="">
        <color
          rgba="0.752941176470588 0.752941176470588 0.752941176470588 1" />
      </material>
    </visual>
    <collision>
      <origin
        xyz="0 0 0"
        rpy="0 0 0" />
      <geometry>
        <mesh
          filename="../meshes/left_thigh_pitch_link.STL" />
      </geometry>
    </collision>
  </link>
  <joint
    name="left_hip_pitch_joint"
    type="revolute">
    <origin
      xyz="0 0.0223 -0.14027"
      rpy="0 0 0" />
    <parent
      link="left_thigh_yaw_link" />
    <child
      link="left_thigh_pitch_link" />
    <axis
      xyz="0 1 0" />
    <limit
      lower="-1.75"
      upper="0.7"
      effort="225"
      velocity="37.38" />
  </joint>
  <link
    name="left_shank_pitch_link">
    <inertial>
      <origin
        xyz="0.00210031094919311 -0.000637785274947166 -0.117872300125325"
        rpy="0 0 0" />
      <mass
        value="1.24868227543803" />
      <inertia
        ixx="0.00824928756171069"
        ixy="-2.79794413903226E-06"
        ixz="0.000145129736052943"
        iyy="0.00861512734755768"
        iyz="3.03174030806406E-05"
        izz="0.00046651622886323" />
    </inertial>
    <visual>
      <origin
        xyz="0 0 0"
        rpy="0 0 0" />
      <geometry>
        <mesh
          filename="../meshes/left_shank_pitch_link.STL" />
      </geometry>
      <material
        name="">
        <color
          rgba="0.752941176470588 0.752941176470588 0.752941176470588 1" />
      </material>
    </visual>
    <collision>
      <origin
        xyz="0 0 0"
        rpy="0 0 0" />
      <geometry>
        <mesh
          filename="../meshes/left_shank_pitch_link.STL" />
      </geometry>
    </collision>
  </link>
  <joint
    name="left_knee_pitch_joint"
    type="revolute">
    <origin
      xyz="0 -0.019512 -0.36"
      rpy="0 0 0" />
    <parent
      link="left_thigh_pitch_link" />
    <child
      link="left_shank_pitch_link" />
    <axis
      xyz="0 1 0" />
    <limit
      lower="-0.09"
      upper="1.92"
      effort="225"
      velocity="37.38" />
  </joint>
  <link
    name="left_foot_pitch_link">
    <inertial>
      <origin
        xyz="-1.07129194404365E-08 -1.1780193374597E-08 1.11022302462516E-16"
        rpy="0 0 0" />
      <mass
        value="0.0574489065896827" />
      <inertia
        ixx="5.30819666123276E-06"
        ixy="1.56156787231189E-14"
        ixz="5.21609499147051E-13"
        iyy="3.81342231185492E-06"
        iyz="-4.61453277397347E-13"
        izz="4.52344367964407E-06" />
    </inertial>
    <visual>
      <origin
        xyz="0 0 0"
        rpy="0 0 0" />
      <geometry>
        <mesh
          filename="../meshes/left_foot_pitch_link.STL" />
      </geometry>
      <material
        name="">
        <color
          rgba="0.752941176470588 0.752941176470588 0.752941176470588 1" />
      </material>
    </visual>
    <collision>
      <origin
        xyz="0 0 0"
        rpy="0 0 0" />
      <geometry>
        <mesh
          filename="../meshes/left_foot_pitch_link.STL" />
      </geometry>
    </collision>
  </link>
  <joint
    name="left_ankle_pitch_joint"
    type="revolute">
    <origin
      xyz="0 -0.00125 -0.34"
      rpy="0 0 0" />
    <parent
      link="left_shank_pitch_link" />
    <child
      link="left_foot_pitch_link" />
    <axis
      xyz="0 1 0" />
    <limit
      lower="-1.05"
      upper="0.52"
      effort="15"
      velocity="20.32" />
  </joint>
  <link
    name="left_foot_roll_link">
    <inertial>
      <origin
        xyz="0.0376148502461927 0.000103133555260948 -0.0383776735275824"
        rpy="0 0 0" />
      <mass
        value="1.07266130913334" />
      <inertia
        ixx="0.000674389796013742"
        ixy="-4.48301744315304E-06"
        ixz="-3.92774611426912E-05"
        iyy="0.00449048620687972"
        iyz="1.89148421598368E-06"
        izz="0.00505384575428989" />
    </inertial>
    <visual>
      <origin
        xyz="0 0 0"
        rpy="0 0 0" />
      <geometry>
        <mesh
          filename="../meshes/left_foot_roll_link.STL" />
      </geometry>
      <material
        name="">
        <color
          rgba="0.752941176470588 0.752941176470588 0.752941176470588 1" />
      </material>
    </visual>
    <collision>
      <origin
        xyz="0 0 0"
        rpy="0 0 0" />
      <geometry>
        <mesh
          filename="../meshes/left_foot_roll_link.STL" />
      </geometry>
    </collision>
  </link>
  <joint
    name="left_ankle_roll_joint"
    type="revolute">
    <origin
      xyz="0 0 0"
      rpy="0 0 0" />
    <parent
      link="left_foot_pitch_link" />
    <child
      link="left_foot_roll_link" />
    <axis
      xyz="1 0 0" />
    <limit
      lower="-0.44"
      upper="0.44"
      effort="30"
      velocity="20.32" />
  </joint>
  <link
    name="right_thigh_roll_link">
    <inertial>
      <origin
        xyz="-0.0140957044365422 3.48414493070714E-05 -0.000246907551615744"
        rpy="0 0 0" />
      <mass
        value="1507.18975344752" />
      <inertia
        ixx="0.879424370598222"
        ixy="-0.000206934332171776"
        ixz="-0.000476032888681939"
        iyy="0.57841325594884"
        iyz="-0.000876371453594059"
        izz="0.784216663825866" />
    </inertial>
    <visual>
      <origin
        xyz="0 0 0"
        rpy="0 0 0" />
      <geometry>
        <mesh
          filename="../meshes/right_thigh_roll_link.STL" />
      </geometry>
      <material
        name="">
        <color
          rgba="0.752941176470588 0.752941176470588 0.752941176470588 1" />
      </material>
    </visual>
    <collision>
      <origin
        xyz="0 0 0"
        rpy="0 0 0" />
      <geometry>
        <mesh
          filename="../meshes/right_thigh_roll_link.STL" />
      </geometry>
    </collision>
  </link>
  <joint
    name="right_hip_roll_joint"
    type="revolute">
    <origin
      xyz="-0.031635 -0.105 -0.0276"
      rpy="0 0 0" />
    <parent
      link="base_link" />
    <child
      link="right_thigh_roll_link" />
    <axis
      xyz="1 0 0" />
    <limit
      lower="-0.79"
      upper="0.09"
      effort="48"
      velocity="12.15" />
  </joint>
  <link
    name="right_thigh_yaw_link">
    <inertial>
      <origin
        xyz="-0.000819589106230034 -0.0303816141480203 -0.0866432405285683"
        rpy="0 0 0" />
      <mass
        value="2.94578866532887" />
      <inertia
        ixx="0.00547980139055797"
        ixy="-5.53880915632546E-05"
        ixz="-0.000111615337834792"
        iyy="0.00833983339689913"
        iyz="0.000476298315056377"
        izz="0.00427180271305018" />
    </inertial>
    <visual>
      <origin
        xyz="0 0 0"
        rpy="0 0 0" />
      <geometry>
        <mesh
          filename="../meshes/right_thigh_yaw_link.STL" />
      </geometry>
      <material
        name="">
        <color
          rgba="0.752941176470588 0.752941176470588 0.752941176470588 1" />
      </material>
    </visual>
    <collision>
      <origin
        xyz="0 0 0"
        rpy="0 0 0" />
      <geometry>
        <mesh
          filename="../meshes/right_thigh_yaw_link.STL" />
      </geometry>
    </collision>
  </link>
  <joint
    name="right_hip_yaw_joint"
    type="revolute">
    <origin
      xyz="0.033135 0 0.00075"
      rpy="0 0 0" />
    <parent
      link="right_thigh_roll_link" />
    <child
      link="right_thigh_yaw_link" />
    <axis
      xyz="0 0 1" />
    <limit
      lower="-0.7"
      upper="0.7"
      effort="66"
      velocity="16.76" />
  </joint>
  <link
    name="right_thigh_pitch_link">
    <inertial>
      <origin
        xyz="0.00208225131631323 0.0285170174872916 -0.0827748137411186"
        rpy="0 0 0" />
      <mass
        value="5.54668411544495" />
      <inertia
        ixx="0.0423264468991171"
        ixy="7.58073343760003E-05"
        ixz="-0.000656232123240726"
        iyy="0.049406240315846"
        iyz="0.000621475446572119"
        izz="0.00802532504277665" />
    </inertial>
    <visual>
      <origin
        xyz="0 0 0"
        rpy="0 0 0" />
      <geometry>
        <mesh
          filename="../meshes/right_thigh_pitch_link.STL" />
      </geometry>
      <material
        name="">
        <color
          rgba="0.752941176470588 0.752941176470588 0.752941176470588 1" />
      </material>
    </visual>
    <collision>
      <origin
        xyz="0 0 0"
        rpy="0 0 0" />
      <geometry>
        <mesh
          filename="../meshes/right_thigh_pitch_link.STL" />
      </geometry>
    </collision>
  </link>
  <joint
    name="right_hip_pitch_joint"
    type="revolute">
    <origin
      xyz="0 -0.0223 -0.14027"
      rpy="0 0 0" />
    <parent
      link="right_thigh_yaw_link" />
    <child
      link="right_thigh_pitch_link" />
    <axis
      xyz="0 1 0" />
    <limit
      lower="-1.75"
      upper="0.7"
      effort="225"
      velocity="37.38" />
  </joint>
  <link
    name="right_shank_pitch_link">
    <inertial>
      <origin
        xyz="0.00210699956087934 0.000587477380229018 -0.117530202661271"
        rpy="0 0 0" />
      <mass
        value="1.2458653370801" />
      <inertia
        ixx="0.00819470690738236"
        ixy="2.87516206953314E-06"
        ixz="0.000144815308956129"
        iyy="0.00856102738082464"
        iyz="-2.66516985686519E-05"
        izz="0.000466503156434759" />
    </inertial>
    <visual>
      <origin
        xyz="0 0 0"
        rpy="0 0 0" />
      <geometry>
        <mesh
          filename="../meshes/right_shank_pitch_link.STL" />
      </geometry>
      <material
        name="">
        <color
          rgba="0.752941176470588 0.752941176470588 0.752941176470588 1" />
      </material>
    </visual>
    <collision>
      <origin
        xyz="0 0 0"
        rpy="0 0 0" />
      <geometry>
        <mesh
          filename="../meshes/right_shank_pitch_link.STL" />
      </geometry>
    </collision>
  </link>
  <joint
    name="right_knee_pitch_joint"
    type="revolute">
    <origin
      xyz="0 0.019762 -0.36"
      rpy="0 0 0" />
    <parent
      link="right_thigh_pitch_link" />
    <child
      link="right_shank_pitch_link" />
    <axis
      xyz="0 1 0" />
    <limit
      lower="-0.09"
      upper="1.92"
      effort="225"
      velocity="37.38" />
  </joint>
  <link
    name="right_foot_pitch_link">
    <inertial>
      <origin
        xyz="-1.07129188298138E-08 -1.17801933208206E-08 -3.33066907387547E-16"
        rpy="0 0 0" />
      <mass
        value="0.0574489065896825" />
      <inertia
        ixx="5.30819666123276E-06"
        ixy="1.56156813225882E-14"
        ixz="5.21609498757624E-13"
        iyy="3.81342231185492E-06"
        iyz="-4.61453278980273E-13"
        izz="4.52344367964405E-06" />
    </inertial>
    <visual>
      <origin
        xyz="0 0 0"
        rpy="0 0 0" />
      <geometry>
        <mesh
          filename="../meshes/right_foot_pitch_link.STL" />
      </geometry>
      <material
        name="">
        <color
          rgba="0.752941176470588 0.752941176470588 0.752941176470588 1" />
      </material>
    </visual>
    <collision>
      <origin
        xyz="0 0 0"
        rpy="0 0 0" />
      <geometry>
        <mesh
          filename="../meshes/right_foot_pitch_link.STL" />
      </geometry>
    </collision>
  </link>
  <joint
    name="right_ankle_pitch_joint"
    type="revolute">
    <origin
      xyz="0 0.00125 -0.34"
      rpy="0 0 0" />
    <parent
      link="right_shank_pitch_link" />
    <child
      link="right_foot_pitch_link" />
    <axis
      xyz="0 1 0" />
    <limit
      lower="-1.05"
      upper="0.52"
      effort="15"
      velocity="20.32" />
  </joint>
  <link
    name="right_foot_roll_link">
    <inertial>
      <origin
        xyz="0.0389014954154843 -0.000322324679783159 -0.0383680937219875"
        rpy="0 0 0" />
      <mass
        value="1.07277352313189" />
      <inertia
        ixx="0.000674294463191695"
        ixy="4.5575076221846E-06"
        ixz="-3.92771056400483E-05"
        iyy="0.00449001786644372"
        iyz="-1.88133873715694E-06"
        izz="0.00505328835030007" />
    </inertial>
    <visual>
      <origin
        xyz="0 0 0"
        rpy="0 0 0" />
      <geometry>
        <mesh
          filename="../meshes/right_foot_roll_link.STL" />
      </geometry>
      <material
        name="">
        <color
          rgba="0.752941176470588 0.752941176470588 0.752941176470588 1" />
      </material>
    </visual>
    <collision>
      <origin
        xyz="0 0 0"
        rpy="0 0 0" />
      <geometry>
        <mesh
          filename="../meshes/right_foot_roll_link.STL" />
      </geometry>
    </collision>
  </link>
  <joint
    name="right_ankle_roll_joint"
    type="revolute">
    <origin
      xyz="0 0 0"
      rpy="0 0 0" />
    <parent
      link="right_foot_pitch_link" />
    <child
      link="right_foot_roll_link" />
    <axis
      xyz="1 0 0" />
    <limit
      lower="-0.44"
      upper="0.44"
      effort="30"
      velocity="20.32" />
  </joint>
  <link
    name="waist_yaw_link">
    <inertial>
      <origin
        xyz="-2.61040489940578E-06 -0.00929340119867471 0.0498715914707374"
        rpy="0 0 0" />
      <mass
        value="1108.09730821923" />
      <inertia
        ixx="0.273496512241418"
        ixy="-0.000297254677067729"
        ixz="0.000224105915581235"
        iyy="0.381020815790297"
        iyz="9.59439725310858E-05"
        izz="0.380800461766641" />
    </inertial>
    <visual>
      <origin
        xyz="0 0 0"
        rpy="0 0 0" />
      <geometry>
        <mesh
          filename="../meshes/waist_yaw_link.STL" />
      </geometry>
      <material
        name="">
        <color
          rgba="0.752941176470588 0.752941176470588 0.752941176470588 1" />
      </material>
    </visual>
    <collision>
      <origin
        xyz="0 0 0"
        rpy="0 0 0" />
      <geometry>
        <mesh
          filename="../meshes/waist_yaw_link.STL" />
      </geometry>
    </collision>
  </link>
  <joint
    name="waist_yaw_joint"
    type="revolute">
    <origin
      xyz="0 0 0"
      rpy="0 0 0" />
    <parent
      link="base_link" />
    <child
      link="waist_yaw_link" />
    <axis
      xyz="0 0 1" />
    <limit
      lower="-1.05"
      upper="1.05"
      effort="66"
      velocity="16.76" />
  </joint>
  <link
    name="waist_pitch_link">
    <inertial>
      <origin
        xyz="0.00218792815453034 -0.00226710724336546 0.040308159759465"
        rpy="0 0 0" />
      <mass
        value="1.54375289331268" />
      <inertia
        ixx="0.00247622232275658"
        ixy="9.45472003682314E-06"
        ixz="6.98903871292122E-05"
        iyy="0.0024875801248184"
        iyz="7.29193831486916E-05"
        izz="0.00117436231563976" />
    </inertial>
    <visual>
      <origin
        xyz="0 0 0"
        rpy="0 0 0" />
      <geometry>
        <mesh
          filename="../meshes/waist_pitch_link.STL" />
      </geometry>
      <material
        name="">
        <color
          rgba="0.752941176470588 0.752941176470588 0.752941176470588 1" />
      </material>
    </visual>
    <collision>
      <origin
        xyz="0 0 0"
        rpy="0 0 0" />
      <geometry>
        <mesh
          filename="../meshes/waist_pitch_link.STL" />
      </geometry>
    </collision>
  </link>
  <joint
    name="waist_pitch_joint"
    type="revolute">
    <origin
      xyz="0 0 0.0869"
      rpy="0 0 0" />
    <parent
      link="waist_yaw_link" />
    <child
      link="waist_pitch_link" />
    <axis
      xyz="0 1 0" />
    <limit
      lower="-0.52"
      upper="1.22"
      effort="66"
      velocity="16.76" />
  </joint>
  <link
    name="waist_roll_link">
    <inertial>
      <origin
        xyz="0.0128336725917207 -4.63444944300007E-06 2.85462872852138E-05"
        rpy="0 0 0" />
      <mass
        value="554.162969695286" />
      <inertia
        ixx="0.244505896140362"
        ixy="0.000142765170925357"
        ixz="-9.19549432138789E-05"
        iyy="0.136548671170817"
        iyz="0.000470107960282726"
        izz="0.136497009673392" />
    </inertial>
    <visual>
      <origin
        xyz="0 0 0"
        rpy="0 0 0" />
      <geometry>
        <mesh
          filename="../meshes/waist_roll_link.STL" />
      </geometry>
      <material
        name="">
        <color
          rgba="0.752941176470588 0.752941176470588 0.752941176470588 1" />
      </material>
    </visual>
    <collision>
      <origin
        xyz="0 0 0"
        rpy="0 0 0" />
      <geometry>
        <mesh
          filename="../meshes/waist_roll_link.STL" />
      </geometry>
    </collision>
  </link>
  <joint
    name="waist_roll_joint"
    type="revolute">
    <origin
      xyz="0.00525 -0.0005 0.081"
      rpy="0 0 0" />
    <parent
      link="waist_pitch_link" />
    <child
      link="waist_roll_link" />
    <axis
      xyz="1 0 0" />
    <limit
      lower="-0.7"
      upper="0.7"
      effort="66"
      velocity="16.76" />
  </joint>
  <link
    name="torso_link">
    <inertial>
      <origin
        xyz="0.000510505175079945 0.000389415319438688 0.0642361142716205"
        rpy="0 0 0" />
      <mass
        value="990.85071583124" />
      <inertia
        ixx="0.273758458441474"
        ixy="-7.55663519795262E-05"
        ixz="-0.000111310202612634"
        iyy="0.462732194303926"
        iyz="0.000480281177121426"
        izz="0.31074174346294" />
    </inertial>
    <visual>
      <origin
        xyz="0 0 0"
        rpy="0 0 0" />
      <geometry>
        <mesh
          filename="../meshes/torso_link.STL" />
      </geometry>
      <material
        name="">
        <color
          rgba="0.752941176470588 0.752941176470588 0.752941176470588 1" />
      </material>
    </visual>
    <collision>
      <origin
        xyz="0 0 0"
        rpy="0 0 0" />
      <geometry>
        <mesh
          filename="../meshes/torso_link.STL" />
      </geometry>
    </collision>
  </link>
  <joint
    name="torso_joint"
    type="fixed">
    <origin
      xyz="-0.00225 0.00057443 0.16035"
      rpy="0 0 0" />
    <parent
      link="waist_roll_link" />
    <child
      link="torso_link" />
    <axis
      xyz="0 0 0" />
  </joint>
  <link
    name="left_upper_arm_pitch_link">
    <inertial>
      <origin
        xyz="0.00187455803941461 0.0949610628888863 4.16878104423368E-05"
        rpy="0 0 0" />
      <mass
        value="337.792664424117" />
      <inertia
        ixx="0.214902919479445"
        ixy="-7.38991831815422E-05"
        ixz="1.7363779507577E-05"
        iyy="0.116317316981664"
        iyz="6.29531501061612E-05"
        izz="0.116477676931581" />
    </inertial>
    <visual>
      <origin
        xyz="0 0 0"
        rpy="0 0 0" />
      <geometry>
        <mesh
          filename="../meshes/left_upper_arm_pitch_link.STL" />
      </geometry>
      <material
        name="">
        <color
          rgba="0.752941176470588 0.752941176470588 0.752941176470588 1" />
      </material>
    </visual>
    <collision>
      <origin
        xyz="0 0 0"
        rpy="0 0 0" />
      <geometry>
        <mesh
          filename="../meshes/left_upper_arm_pitch_link.STL" />
      </geometry>
    </collision>
  </link>
  <joint
    name="left_shoulder_pitch_link"
    type="revolute">
    <origin
      xyz="0 0.10128 0.046651"
      rpy="0.43275 0 0" />
    <parent
      link="torso_link" />
    <child
      link="left_upper_arm_pitch_link" />
    <axis
      xyz="0 1 0" />
    <limit
      lower="-2.79"
      upper="1.92"
      effort="38"
      velocity="9.11" />
  </joint>
  <link
    name="left_upper_arm_roll_link">
    <inertial>
      <origin
        xyz="0.0141861335845524 -0.382816062951232 -0.00812886474710051"
        rpy="0 0 0" />
      <mass
        value="0.801935018829574" />
      <inertia
        ixx="0.000333065494159242"
        ixy="3.36462724905319E-05"
        ixz="3.8324806327022E-05"
        iyy="0.000234506487956696"
        iyz="3.81991885988805E-05"
        izz="0.000256521707778392" />
    </inertial>
    <visual>
      <origin
        xyz="0 0 0"
        rpy="0 0 0" />
      <geometry>
        <mesh
          filename="../meshes/left_upper_arm_roll_link.STL" />
      </geometry>
      <material
        name="">
        <color
          rgba="0.752941176470588 0.752941176470588 0.752941176470588 1" />
      </material>
    </visual>
    <collision>
      <origin
        xyz="0 0 0"
        rpy="0 0 0" />
      <geometry>
        <mesh
          filename="../meshes/left_upper_arm_roll_link.STL" />
      </geometry>
    </collision>
  </link>
  <joint
    name="left_shoulder_roll_joint"
    type="revolute">
    <origin
      xyz="0 0.09515 0"
      rpy="-0.43275 0 0" />
    <parent
      link="left_upper_arm_pitch_link" />
    <child
      link="left_upper_arm_roll_link" />
    <axis
      xyz="1 0 0" />
    <limit
      lower="-0.57"
      upper="2.53"
      effort="38"
      velocity="9.11" />
  </joint>
  <link
    name="left_upper_arm_yaw_link">
    <inertial>
      <origin
        xyz="-2.67971850725357E-05 -0.00106838564052969 -0.0833577512054164"
        rpy="0 0 0" />
      <mass
        value="0.24718891999306" />
      <inertia
        ixx="0.00065710658054018"
        ixy="6.99417623211427E-09"
        ixz="5.55765716661579E-08"
        iyy="0.000642059032324533"
        iyz="-4.65942183133926E-05"
        izz="0.000144067518685082" />
    </inertial>
    <visual>
      <origin
        xyz="0 0 0"
        rpy="0 0 0" />
      <geometry>
        <mesh
          filename="../meshes/left_upper_arm_yaw_link.STL" />
      </geometry>
      <material
        name="">
        <color
          rgba="0.752941176470588 0.752941176470588 0.752941176470588 1" />
      </material>
    </visual>
    <collision>
      <origin
        xyz="0 0 0"
        rpy="0 0 0" />
      <geometry>
        <mesh
          filename="../meshes/left_upper_arm_yaw_link.STL" />
      </geometry>
    </collision>
  </link>
  <joint
    name="left_shoulder_yaw_joint"
    type="revolute">
    <origin
      xyz="0 0.04 -0.0749"
      rpy="0 0 0" />
    <parent
      link="left_upper_arm_roll_link" />
    <child
      link="left_upper_arm_yaw_link" />
    <axis
      xyz="0 0 1" />
    <limit
      lower="-2.97"
      upper="2.97"
      effort="30"
      velocity="7.33" />
  </joint>
  <link
    name="left_lower_arm_pitch_link">
    <inertial>
      <origin
        xyz="4.14851675234473E-09 0.0131650679993903 -0.0230416379628237"
        rpy="0 0 0" />
      <mass
        value="0.119136224927269" />
      <inertia
        ixx="3.54626254983751E-05"
        ixy="9.91162678781598E-10"
        ixz="-1.00128634082934E-09"
        iyy="3.78087064231645E-05"
        iyz="7.18220802579934E-06"
        izz="3.21766969137428E-05" />
    </inertial>
    <visual>
      <origin
        xyz="0 0 0"
        rpy="0 0 0" />
      <geometry>
        <mesh
          filename="../meshes/left_lower_arm_pitch_link.STL" />
      </geometry>
      <material
        name="">
        <color
          rgba="0.752941176470588 0.752941176470588 0.752941176470588 1" />
      </material>
    </visual>
    <collision>
      <origin
        xyz="0 0 0"
        rpy="0 0 0" />
      <geometry>
        <mesh
          filename="../meshes/left_lower_arm_pitch_link.STL" />
      </geometry>
    </collision>
  </link>
  <joint
    name="left_elbow_pitch_joint"
    type="revolute">
    <origin
      xyz="0 0.0010503 -0.1786"
      rpy="0 0 0" />
    <parent
      link="left_upper_arm_yaw_link" />
    <child
      link="left_lower_arm_pitch_link" />
    <axis
      xyz="0 1 0" />
    <limit
      lower="-2.27"
      upper="2.27"
      effort="30"
      velocity="7.33" />
  </joint>
  <link
    name="left_hand_yaw_link">
    <inertial>
      <origin
        xyz="0.00111372069651955 0.00466841277721133 -0.0861019048255408"
        rpy="0 0 0" />
      <mass
        value="314.639689930468" />
      <inertia
        ixx="0.0642922449022753"
        ixy="9.2887303532299E-07"
        ixz="4.73899075181033E-05"
        iyy="0.0338516306787626"
        iyz="7.72535767191563E-05"
        izz="0.0387311287235261" />
    </inertial>
    <visual>
      <origin
        xyz="0 0 0"
        rpy="0 0 0" />
      <geometry>
        <mesh
          filename="../meshes/left_hand_yaw_link.STL" />
      </geometry>
      <material
        name="">
        <color
          rgba="0.752941176470588 0.752941176470588 0.752941176470588 1" />
      </material>
    </visual>
    <collision>
      <origin
        xyz="0 0 0"
        rpy="0 0 0" />
      <geometry>
        <mesh
          filename="../meshes/left_hand_yaw_link.STL" />
      </geometry>
    </collision>
  </link>
  <joint
    name="left_wrist_yaw_joint"
    type="revolute">
    <origin
      xyz="0 0 -0.05945"
      rpy="0 0 0" />
    <parent
      link="left_lower_arm_pitch_link" />
    <child
      link="left_hand_yaw_link" />
    <axis
      xyz="0 0 1" />
    <limit
      lower="-2.97"
      upper="2.97"
      effort="10.2"
      velocity="24.4" />
  </joint>
  <link
    name="left_hand_roll_link">
    <inertial>
      <origin
        xyz="1.91911530555977E-08 -0.000244128701131108 -1.08190994566049E-08"
        rpy="0 0 0" />
      <mass
        value="0.00525337141813314" />
      <inertia
        ixx="6.5747595661794E-08"
        ixy="-6.85771405863614E-13"
        ixz="-2.20713600305862E-12"
        iyy="3.52512694086109E-07"
        iyz="-1.46665978685243E-15"
        izz="3.52673983602149E-07" />
    </inertial>
    <visual>
      <origin
        xyz="0 0 0"
        rpy="0 0 0" />
      <geometry>
        <mesh
          filename="../meshes/left_hand_roll_link.STL" />
      </geometry>
      <material
        name="">
        <color
          rgba="0.752941176470588 0.752941176470588 0.752941176470588 1" />
      </material>
    </visual>
    <collision>
      <origin
        xyz="0 0 0"
        rpy="0 0 0" />
      <geometry>
        <mesh
          filename="../meshes/left_hand_roll_link.STL" />
      </geometry>
    </collision>
  </link>
  <joint
    name="left_wrist_joint"
    type="revolute">
    <origin
      xyz="0 0 -0.19115"
      rpy="0 0 0" />
    <parent
      link="left_hand_yaw_link" />
    <child
      link="left_hand_roll_link" />
    <axis
      xyz="1 0 0" />
    <limit
      lower="-0.87"
      upper="0.96"
      effort="3.95"
      velocity="27.96" />
  </joint>
  <link
    name="left_hand_pitch_link">
    <inertial>
      <origin
        xyz="5.23096457039074E-07 0.00566604926534681 -0.00937684025467798"
        rpy="0 0 0" />
      <mass
        value="0.0499845091495573" />
      <inertia
        ixx="6.65778993760503E-06"
        ixy="6.91863316690959E-11"
        ixz="2.13962863839274E-10"
        iyy="6.31126304401162E-06"
        iyz="-4.3130292951531E-07"
        izz="8.67570163649692E-06" />
    </inertial>
    <visual>
      <origin
        xyz="0 0 0"
        rpy="0 0 0" />
      <geometry>
        <mesh
          filename="../meshes/left_hand_pitch_link.STL" />
      </geometry>
      <material
        name="">
        <color
          rgba="0.752941176470588 0.752941176470588 0.752941176470588 1" />
      </material>
    </visual>
    <collision>
      <origin
        xyz="0 0 0"
        rpy="0 0 0" />
      <geometry>
        <mesh
          filename="../meshes/left_hand_pitch_link.STL" />
      </geometry>
    </collision>
  </link>
  <joint
    name="left_wrist_pitch_joint"
    type="revolute">
    <origin
      xyz="0 0 0"
      rpy="0 0 0" />
    <parent
      link="left_hand_roll_link" />
    <child
      link="left_hand_pitch_link" />
    <axis
      xyz="0 1 0" />
    <limit
      lower="-0.61"
      upper="0.61"
      effort="3.95"
      velocity="27.96" />
  </joint>


  <link
    name="left_end_effector_link">
  </link>
  <joint
    name="left_end_effector_joint"
    type="fixed">
    <origin
      xyz="0 0 0"
      rpy="0 0 0" />
    <parent
      link="left_hand_pitch_link" />
    <child
      link="left_end_effector_link" />
  </joint>




  <link
    name="L_hand_base_link">
    <inertial>
      <origin
        xyz="-0.0004466 -0.009158 -0.04325"
        rpy="0 0 0" />
      <mass
        value="0.306" />
      <inertia
        ixx="0.0003042"
        ixy="-5E-07"
        ixz="1E-07"
        iyy="0.0004110"
        iyz="4E-08"
        izz="0.0001951" />
    </inertial>
    <visual>
      <origin
        xyz="0 0 0"
        rpy="0 0 0" />
      <geometry>
        <mesh
          filename="../meshes/fourier_hand_6dof/L_hand_base_link.STL" />
      </geometry>
      <material
        name="">
        <color
          rgba="0.86667 0.86667 0.8902 1" />
      </material>
    </visual>
    <collision>
      <origin
        xyz="0 0 0"
        rpy="0 0 0" />
      <geometry>
        <mesh
          filename="../meshes/fourier_hand_6dof/L_hand_base_link.STL" />
      </geometry>
    </collision>
  </link>
  <joint
    name="L_hand_base_joint"
    type="fixed">
    <origin
      xyz="0 0 -0.021"
      rpy="0 0 0" />
    <parent
      link="left_end_effector_link" />
    <child
      link="L_hand_base_link" />
    <axis
      xyz="0 0 0" />
  </joint>
  <link
    name="L_thumb_proximal_base_link">
    <inertial>
      <origin
        xyz="0.011017 -2.4767E-05 0.00077605"
        rpy="0 0 0" />
      <mass
        value="0.00948527" />
      <inertia
        ixx="3E-07"
        ixy="1E-08"
        ixz="-4E-08"
        iyy="9.5E-07"
        iyz="-1E-08"
        izz="9.7E-07" />
    </inertial>
    <visual>
      <origin
        xyz="0 0 0"
        rpy="0 0 0" />
      <geometry>
        <mesh
          filename="../meshes/fourier_hand_6dof/L_thumb_proximal_base_link.STL" />
      </geometry>
      <material
        name="">
        <color
          rgba="0.8902 0.8902 0.91373 1" />
      </material>
    </visual>
    <collision>
      <origin
        xyz="0 0 0"
        rpy="0 0 0" />
      <geometry>
        <mesh
          filename="../meshes/fourier_hand_6dof/L_thumb_proximal_base_link.STL" />
      </geometry>
    </collision>
  </link>
  <joint
    name="L_thumb_proximal_yaw_joint"
    type="revolute">
    <origin
      xyz="0.022 -0.015498 -0.025093"
      rpy="0 -1.221E-05 0" />
    <parent
      link="L_hand_base_link" />
    <child
      link="L_thumb_proximal_base_link" />
    <axis
      xyz="0 0 1" />
    <limit
      lower="-1.74"
      upper="0"
      effort="10"
      velocity="0.8" />
  </joint>
  <link
    name="L_thumb_proximal_link">
    <inertial>
      <origin
        xyz="0.03196306 -0.00014118 -2.861E-05"
        rpy="0 0 0" />
      <mass
        value="0.07347612" />
      <inertia
        ixx="1.131E-05"
        ixy="1E-07"
        ixz="4E-08"
        iyy="3.183E-05"
        iyz="-1E-08"
        izz="3.376E-05" />
    </inertial>
    <visual>
      <origin
        xyz="0 0 0"
        rpy="0 0 0" />
      <geometry>
        <mesh
          filename="../meshes/fourier_hand_6dof/L_thumb_proximal_link.STL" />
      </geometry>
      <material
        name="">
        <color
          rgba="0.86667 0.86667 0.8902 1" />
      </material>
    </visual>
    <collision>
      <origin
        xyz="0 0 0"
        rpy="0 0 0" />
      <geometry>
        <mesh
          filename="../meshes/fourier_hand_6dof/L_thumb_proximal_link.STL" />
      </geometry>
    </collision>
  </link>
  <joint
    name="L_thumb_proximal_pitch_joint"
    type="revolute">
    <origin
      xyz="0.02175 0 0"
      rpy="-1.5707 0 0" />
    <parent
      link="L_thumb_proximal_base_link" />
    <child
      link="L_thumb_proximal_link" />
    <axis
      xyz="0 0 1" />
    <limit
      lower="0"
      upper="1.22"
      effort="10"
      velocity="0.8" />
  </joint>
  <link
    name="L_thumb_distal_link">
    <inertial>
      <origin
        xyz="0.01321529 -0.00326134 0"
        rpy="0 0 0" />
      <mass
        value="0.02031766" />
      <inertia
        ixx="9.2E-07"
        ixy="-9E-08"
        ixz="0"
        iyy="2.48E-06"
        iyz="0"
        izz="2.34E-06" />
    </inertial>
    <visual>
      <origin
        xyz="0 0 0"
        rpy="0 0 0" />
      <geometry>
        <mesh
          filename="../meshes/fourier_hand_6dof/L_thumb_distal_link.STL" />
      </geometry>
      <material
        name="">
        <color
          rgba="0.79216 0.81961 0.93333 1" />
      </material>
    </visual>
    <collision>
      <origin
        xyz="0 0 0"
        rpy="0 0 0" />
      <geometry>
        <mesh
          filename="../meshes/fourier_hand_6dof/L_thumb_distal_link.STL" />
      </geometry>
    </collision>
  </link>
  <joint
    name="L_thumb_distal_joint"
    type="revolute">
    <origin
      xyz="0.061549 0.0074616 0"
      rpy="0 0 1.221E-05" />
    <parent
      link="L_thumb_proximal_link" />
    <child
      link="L_thumb_distal_link" />
    <axis
      xyz="0 0 1" />
    <limit
      lower="0"
      upper="1.23"
      effort="10"
      velocity="0.8" />
    <mimic
      joint="L_thumb_proximal_pitch_joint"
      multiplier="0.974"
      offset="0" />
  </joint>

  <link name="L_thumb_tip_link">
    <visual>
      <origin
        xyz="0 0 0"
        rpy="0 0 0" />
      <geometry>
        <sphere radius="0.005" />
      </geometry>
      <material name="yellow">
        <color rgba="0.9 1 0 1" />
      </material>
    </visual>
  </link>
  <joint name="L_thumb_tip_joint" type="fixed">
    <parent link="L_thumb_distal_link" />
    <child link="L_thumb_tip_link" />
    <origin rpy="0 0 0" xyz="0.031 -0.001 0" />
  </joint>


  <link
    name="L_index_proximal_link">
    <inertial>
      <origin
        xyz="0.0095993 0.000443 2.96E-06"
        rpy="0 0 0" />
      <mass
        value="0.019117" />
      <inertia
        ixx="8.6E-07"
        ixy="1.2E-07"
        ixz="0"
        iyy="3.71E-06"
        iyz="0"
        izz="3.85E-06" />
    </inertial>
    <visual>
      <origin
        xyz="0 0 0"
        rpy="0 0 0" />
      <geometry>
        <mesh
          filename="../meshes/fourier_hand_6dof/L_index_proximal_link.STL" />
      </geometry>
      <material
        name="">
        <color
          rgba="0.86667 0.86667 0.8902 1" />
      </material>
    </visual>
    <collision>
      <origin
        xyz="0 0 0"
        rpy="0 0 0" />
      <geometry>
        <mesh
          filename="../meshes/fourier_hand_6dof/L_index_proximal_link.STL" />
      </geometry>
    </collision>
  </link>
  <joint
    name="L_index_proximal_joint"
    type="revolute">
    <origin
      xyz="0.026869 -0.012293 -0.095989"
      rpy="0.0013057 1.5184 0.0013039" />
    <parent
      link="L_hand_base_link" />
    <child
      link="L_index_proximal_link" />
    <axis
      xyz="0 0 1" />
    <limit
      lower="-1.57"
      upper="0"
      effort="10"
      velocity="0.8" />
  </joint>
  <link
    name="L_index_intermediate_link">
    <inertial>
      <origin
        xyz="0.01800421 0.00300042 -9.23E-06"
        rpy="0 0 0" />
      <mass
        value="0.01292544" />
      <inertia
        ixx="3.7E-07"
        ixy="2.5E-07"
        ixz="0"
        iyy="2.01E-06"
        iyz="0"
        izz="2.04E-06" />
    </inertial>
    <visual>
      <origin
        xyz="0 0 0"
        rpy="0 0 0" />
      <geometry>
        <mesh
          filename="../meshes/fourier_hand_6dof/L_index_intermediate_link.STL" />
      </geometry>
      <material
        name="">
        <color
          rgba="0.79216 0.81961 0.93333 1" />
      </material>
    </visual>
    <collision>
      <origin
        xyz="0 0 0"
        rpy="0 0 0" />
      <geometry>
        <mesh
          filename="../meshes/fourier_hand_6dof/L_index_intermediate_link.STL" />
      </geometry>
    </collision>
  </link>
  <joint
    name="L_index_intermediate_joint"
    type="revolute">
    <origin
      xyz="0.031532 -0.0054551 0"
      rpy="0 0 -6.8256E-05" />
    <parent
      link="L_index_proximal_link" />
    <child
      link="L_index_intermediate_link" />
    <axis
      xyz="0 0 1" />
    <limit
      lower="-1.74"
      upper="0"
      effort="10"
      velocity="0.8" />
    <mimic
      joint="L_index_proximal_joint"
      multiplier="1.128"
      offset="0" />
  </joint>

  <link name="L_index_tip_link">
    <visual>
      <origin
        xyz="0 0 0"
        rpy="0 0 0" />
      <geometry>
        <sphere radius="0.005" />
      </geometry>
      <material name="yellow">
        <color rgba="0.9 1 0 1" />
      </material>
    </visual>
  </link>
  <joint name="L_index_tip_joint" type="fixed">
    <parent link="L_index_intermediate_link" />
    <child link="L_index_tip_link" />
    <origin rpy="0 0 0" xyz="0.038 -0.0015 0" />
  </joint>


  <link
    name="L_middle_proximal_link">
    <inertial>
      <origin
        xyz="0.00955708 0.00071862 2.96E-06"
        rpy="0 0 0" />
      <mass
        value="0.01911771" />
      <inertia
        ixx="8.6E-07"
        ixy="6E-08"
        ixz="0"
        iyy="3.72E-06"
        iyz="0"
        izz="3.85E-06" />
    </inertial>
    <visual>
      <origin
        xyz="0 0 0"
        rpy="0 0 0" />
      <geometry>
        <mesh
          filename="../meshes/fourier_hand_6dof/L_middle_proximal_link.STL" />
      </geometry>
      <material
        name="">
        <color
          rgba="0.8902 0.8902 0.91373 1" />
      </material>
    </visual>
    <collision>
      <origin
        xyz="0 0 0"
        rpy="0 0 0" />
      <geometry>
        <mesh
          filename="../meshes/fourier_hand_6dof/L_middle_proximal_link.STL" />
      </geometry>
    </collision>
  </link>
  <joint
    name="L_middle_proximal_joint"
    type="revolute">
    <origin
      xyz="0.0085012 -0.012293 -0.097993"
      rpy="1.394 1.5707 1.394" />
    <parent
      link="L_hand_base_link" />
    <child
      link="L_middle_proximal_link" />
    <axis
      xyz="0 0 1" />
    <limit
      lower="-1.57"
      upper="0"
      effort="10"
      velocity="0.8" />
  </joint>
  <link
    name="L_middle_intermediate_link">
    <inertial>
      <origin
        xyz="0.02127931 0.00408456 -9.98E-06"
        rpy="0 0 0" />
      <mass
        value="0.01535007" />
      <inertia
        ixx="4.1E-07"
        ixy="2.2E-07"
        ixz="0"
        iyy="3.28E-06"
        iyz="0"
        izz="3.29E-06" />
    </inertial>
    <visual>
      <origin
        xyz="0 0 0"
        rpy="0 0 0" />
      <geometry>
        <mesh
          filename="../meshes/fourier_hand_6dof/L_middle_intermediate_link.STL" />
      </geometry>
      <material
        name="">
        <color
          rgba="0.79216 0.81961 0.93333 1" />
      </material>
    </visual>
    <collision>
      <origin
        xyz="0 0 0"
        rpy="0 0 0" />
      <geometry>
        <mesh
          filename="../meshes/fourier_hand_6dof/L_middle_intermediate_link.STL" />
      </geometry>
    </collision>
  </link>
  <joint
    name="L_middle_intermediate_joint"
    type="revolute">
    <origin
      xyz="0.031662 -0.0046408 0"
      rpy="0 0 -6.835E-05" />
    <parent
      link="L_middle_proximal_link" />
    <child
      link="L_middle_intermediate_link" />
    <axis
      xyz="0 0 1" />
    <limit
      lower="-1.74"
      upper="0"
      effort="10"
      velocity="0.8" />
    <mimic
      joint="L_middle_proximal_joint"
      multiplier="1.131"
      offset="0" />
  </joint>

  <link name="L_middle_tip_link">
    <visual>
      <origin
        xyz="0 0 0"
        rpy="0 0 0" />
      <geometry>
        <sphere radius="0.005" />
      </geometry>
      <material name="yellow">
        <color rgba="0.9 1 0 1" />
      </material>
    </visual>
  </link>
  <joint name="L_middle_tip_joint" type="fixed">
    <parent link="L_middle_intermediate_link" />
    <child link="L_middle_tip_link" />
    <origin rpy="0 0 0" xyz="0.045 0.0005 0" />
  </joint>


  <link
    name="L_ring_proximal_link">
    <inertial>
      <origin
        xyz="0.00959983 0.0004431 2.96E-06"
        rpy="0 0 0" />
      <mass
        value="0.01911771" />
      <inertia
        ixx="8.6E-07"
        ixy="1.2E-07"
        ixz="0"
        iyy="3.71E-06"
        iyz="0"
        izz="3.85E-06" />
    </inertial>
    <visual>
      <origin
        xyz="0 0 0"
        rpy="0 0 0" />
      <geometry>
        <mesh
          filename="../meshes/fourier_hand_6dof/L_ring_proximal_link.STL" />
      </geometry>
      <material
        name="">
        <color
          rgba="0.8902 0.8902 0.91373 1" />
      </material>
    </visual>
    <collision>
      <origin
        xyz="0 0 0"
        rpy="0 0 0" />
      <geometry>
        <mesh
          filename="../meshes/fourier_hand_6dof/L_ring_proximal_link.STL" />
      </geometry>
    </collision>
  </link>
  <joint
    name="L_ring_proximal_joint"
    type="revolute">
    <origin
      xyz="-0.00996 -0.012293 -0.097938"
      rpy="3.1403 1.5184 3.1403" />
    <parent
      link="L_hand_base_link" />
    <child
      link="L_ring_proximal_link" />
    <axis
      xyz="0 0 1" />
    <limit
      lower="-1.57"
      upper="0"
      effort="10"
      velocity="0.8" />
  </joint>
  <link
    name="L_ring_intermediate_link">
    <inertial>
      <origin
        xyz="0.01800421 0.00300042 -9.23E-06"
        rpy="0 0 0" />
      <mass
        value="0.01292544" />
      <inertia
        ixx="3.7E-07"
        ixy="2.5E-07"
        ixz="0"
        iyy="2.01E-06"
        iyz="0"
        izz="2.04E-06" />
    </inertial>
    <visual>
      <origin
        xyz="0 0 0"
        rpy="0 0 0" />
      <geometry>
        <mesh
          filename="../meshes/fourier_hand_6dof/L_ring_intermediate_link.STL" />
      </geometry>
      <material
        name="">
        <color
          rgba="0.79216 0.81961 0.93333 1" />
      </material>
    </visual>
    <collision>
      <origin
        xyz="0 0 0"
        rpy="0 0 0" />
      <geometry>
        <mesh
          filename="../meshes/fourier_hand_6dof/L_ring_intermediate_link.STL" />
      </geometry>
    </collision>
  </link>
  <joint
    name="L_ring_intermediate_joint"
    type="revolute">
    <origin
      xyz="0.031532 -0.0054551 0"
      rpy="0 0 -6.8256E-05" />
    <parent
      link="L_ring_proximal_link" />
    <child
      link="L_ring_intermediate_link" />
    <axis
      xyz="0 0 1" />
    <limit
      lower="-1.74"
      upper="0"
      effort="10"
      velocity="0.8" />
    <mimic
      joint="L_ring_proximal_joint"
      multiplier="1.143"
      offset="0" />
  </joint>

  <link name="L_ring_tip_link">
    <visual>
      <origin
        xyz="0 0 0"
        rpy="0 0 0" />
      <geometry>
        <sphere radius="0.005" />
      </geometry>
      <material name="green">
        <color rgba="0.9 1 0 1" />
      </material>
    </visual>
  </link>
  <joint name="L_ring_tip_joint" type="fixed">
    <parent link="L_ring_intermediate_link" />
    <child link="L_ring_tip_link" />
    <origin rpy="0 0 0" xyz="0.038 -0.002 0" />
  </joint>


  <link
    name="L_pinky_proximal_link">
    <inertial>
      <origin
        xyz="0.00964414 9.378E-05 2.96E-06"
        rpy="0 0 0" />
      <mass
        value="0.01911771" />
      <inertia
        ixx="8.8E-07"
        ixy="2E-07"
        ixz="0"
        iyy="3.7E-06"
        iyz="0"
        izz="3.85E-06" />
    </inertial>
    <visual>
      <origin
        xyz="0 0 0"
        rpy="0 0 0" />
      <geometry>
        <mesh
          filename="../meshes/fourier_hand_6dof/L_pinky_proximal_link.STL" />
      </geometry>
      <material
        name="">
        <color
          rgba="0.8902 0.8902 0.91373 1" />
      </material>
    </visual>
    <collision>
      <origin
        xyz="0 0 0"
        rpy="0 0 0" />
      <geometry>
        <mesh
          filename="../meshes/fourier_hand_6dof/L_pinky_proximal_link.STL" />
      </geometry>
    </collision>
  </link>
  <joint
    name="L_pinky_proximal_joint"
    type="revolute">
    <origin
      xyz="-0.028227 -0.012293 -0.096013"
      rpy="3.1409 1.4661 3.1409" />
    <parent
      link="L_hand_base_link" />
    <child
      link="L_pinky_proximal_link" />
    <axis
      xyz="0 0 1" />
    <limit
      lower="-1.57"
      upper="0"
      effort="10"
      velocity="0.8" />
  </joint>
  <link
    name="L_pinky_intermediate_link">
    <inertial>
      <origin
        xyz="0.01609604 0.00118817 -8.72E-06"
        rpy="0 0 0" />
      <mass
        value="0.00568707" />
      <inertia
        ixx="1.7E-07"
        ixy="1.3E-07"
        ixz="0"
        iyy="6.2E-07"
        iyz="0"
        izz="6.7E-07" />
    </inertial>
    <visual>
      <origin
        xyz="0 0 0"
        rpy="0 0 0" />
      <geometry>
        <mesh
          filename="../meshes/fourier_hand_6dof/L_pinky_intermediate_link.STL" />
      </geometry>
      <material
        name="">
        <color
          rgba="0.79216 0.81961 0.93333 1" />
      </material>
    </visual>
    <collision>
      <origin
        xyz="0 0 0"
        rpy="0 0 0" />
      <geometry>
        <mesh
          filename="../meshes/fourier_hand_6dof/L_pinky_intermediate_link.STL" />
      </geometry>
    </collision>
  </link>
  <joint
    name="L_pinky_intermediate_joint"
    type="revolute">
    <origin
      xyz="0.031338 -0.0064763 0"
      rpy="0 0 -6.7976E-05" />
    <parent
      link="L_pinky_proximal_link" />
    <child
      link="L_pinky_intermediate_link" />
    <axis
      xyz="0 0 1" />
    <limit
      lower="-1.74"
      upper="0"
      effort="10"
      velocity="0.8" />
    <mimic
      joint="L_pinky_proximal_joint"
      multiplier="1.129"
      offset="0" />
  </joint>

  <link name="L_pinky_tip_link">
    <visual>
      <origin
        xyz="0 0 0"
        rpy="0 0 0" />
      <geometry>
        <sphere radius="0.005" />
      </geometry>
      <material name="yellow">
        <color rgba="0.9 1 0 1" />
      </material>
    </visual>
  </link>
  <joint name="L_pinky_tip_joint" type="fixed">
    <parent link="L_pinky_intermediate_link" />
    <child link="L_pinky_tip_link" />
    <origin rpy="0 0 0" xyz="0.031 -0.0040 0" />
  </joint>





  <link
    name="right_upper_arm_pitch_link">
    <inertial>
      <origin
        xyz="0.00187476653229329 -0.0950328813762511 -2.93153965600923E-05"
        rpy="0 0 0" />
      <mass
        value="337.792641660461" />
      <inertia
        ixx="0.214903786794848"
        ixy="-1.6445735560604E-05"
        ixz="-7.4769659402543E-05"
        iyy="0.116553239093999"
        iyz="-6.16990904214916E-05"
        izz="0.116240873554865" />
    </inertial>
    <visual>
      <origin
        xyz="0 0 0"
        rpy="0 0 0" />
      <geometry>
        <mesh
          filename="../meshes/right_upper_arm_pitch_link.STL" />
      </geometry>
      <material
        name="">
        <color
          rgba="0.752941176470588 0.752941176470588 0.752941176470588 1" />
      </material>
    </visual>
    <collision>
      <origin
        xyz="0 0 0"
        rpy="0 0 0" />
      <geometry>
        <mesh
          filename="../meshes/right_upper_arm_pitch_link.STL" />
      </geometry>
    </collision>
  </link>
  <joint
    name="right_shoulder_pitch_joint"
    type="revolute">
    <origin
      xyz="0 -0.10128 0.046651"
      rpy="-0.43272 0 0" />
    <parent
      link="torso_link" />
    <child
      link="right_upper_arm_pitch_link" />
    <axis
      xyz="0 1 0" />
    <limit
      lower="-2.79"
      upper="1.79"
      effort="38"
      velocity="9.11" />
  </joint>
  <link
    name="right_upper_arm_roll_link">
    <inertial>
      <origin
        xyz="0.0141861335845534 -0.00812614280222856 -0.00947140052088186"
        rpy="0 0 0" />
      <mass
        value="0.801935018829574" />
      <inertia
        ixx="0.000333065494159242"
        ixy="3.3646272490532E-05"
        ixz="3.83248063270219E-05"
        iyy="0.000234506487956696"
        iyz="3.81991885988805E-05"
        izz="0.000256521707778392" />
    </inertial>
    <visual>
      <origin
        xyz="0 0 0"
        rpy="0 0 0" />
      <geometry>
        <mesh
          filename="../meshes/right_upper_arm_roll_link.STL" />
      </geometry>
      <material
        name="">
        <color
          rgba="0.752941176470588 0.752941176470588 0.752941176470588 1" />
      </material>
    </visual>
    <collision>
      <origin
        xyz="0 0 0"
        rpy="0 0 0" />
      <geometry>
        <mesh
          filename="../meshes/right_upper_arm_roll_link.STL" />
      </geometry>
    </collision>
  </link>
  <joint
    name="right_shoulder_roll_joint"
    type="revolute">
    <origin
      xyz="0 -0.09515 0"
      rpy="0.43275 0 0" />
    <parent
      link="right_upper_arm_pitch_link" />
    <child
      link="right_upper_arm_roll_link" />
    <axis
      xyz="1 0 0" />
    <limit
      lower="-2.53"
      upper="0.57"
      effort="38"
      velocity="9.11" />
  </joint>
  <link
    name="right_upper_arm_yaw_link">
    <inertial>
      <origin
        xyz="1.40476256882405E-05 0.00106838740499227 -0.0833330516780267"
        rpy="0 0 0" />
      <mass
        value="0.24715073590447" />
      <inertia
        ixx="0.000656911815011772"
        ixy="-7.97587648805517E-08"
        ixz="-2.11190014879744E-08"
        iyy="0.000641876514448525"
        iyz="4.66190645404105E-05"
        izz="0.000143986023847658" />
    </inertial>
    <visual>
      <origin
        xyz="0 0 0"
        rpy="0 0 0" />
      <geometry>
        <mesh
          filename="../meshes/right_upper_arm_yaw_link.STL" />
      </geometry>
      <material
        name="">
        <color
          rgba="0.752941176470588 0.752941176470588 0.752941176470588 1" />
      </material>
    </visual>
    <collision>
      <origin
        xyz="0 0 0"
        rpy="0 0 0" />
      <geometry>
        <mesh
          filename="../meshes/right_upper_arm_yaw_link.STL" />
      </geometry>
    </collision>
  </link>
  <joint
    name="right_shoulder_yaw_joint"
    type="revolute">
    <origin
      xyz="0 -0.04 -0.0709"
      rpy="0 0 0" />
    <parent
      link="right_upper_arm_roll_link" />
    <child
      link="right_upper_arm_yaw_link" />
    <axis
      xyz="0 0 1" />
    <limit
      lower="-2.97"
      upper="2.97"
      effort="30"
      velocity="7.33" />
  </joint>
  <link
    name="right_lower_arm_pitch_link">
    <inertial>
      <origin
        xyz="-4.97999508297653E-09 -0.0131650706803348 -0.0230416375381059"
        rpy="0 0 0" />
      <mass
        value="0.119136183538177" />
      <inertia
        ixx="3.54626201604533E-05"
        ixy="9.90716098481174E-10"
        ixz="1.00117039207124E-09"
        iyy="3.78087008379145E-05"
        iyz="-7.1822081181631E-06"
        izz="3.21766903490826E-05" />
    </inertial>
    <visual>
      <origin
        xyz="0 0 0"
        rpy="0 0 0" />
      <geometry>
        <mesh
          filename="../meshes/right_lower_arm_pitch_link.STL" />
      </geometry>
      <material
        name="">
        <color
          rgba="0.752941176470588 0.752941176470588 0.752941176470588 1" />
      </material>
    </visual>
    <collision>
      <origin
        xyz="0 0 0"
        rpy="0 0 0" />
      <geometry>
        <mesh
          filename="../meshes/right_lower_arm_pitch_link.STL" />
      </geometry>
    </collision>
  </link>
  <joint
    name="right_elbow_pitch_joint"
    type="revolute">
    <origin
      xyz="0 -0.0010503 -0.1786"
      rpy="0 0 0" />
    <parent
      link="right_upper_arm_yaw_link" />
    <child
      link="right_lower_arm_pitch_link" />
    <axis
      xyz="0 1 0" />
    <limit
      lower="-2.27"
      upper="2.27"
      effort="30"
      velocity="7.33" />
  </joint>
  <link
    name="right_hand_yaw_link">
    <inertial>
      <origin
        xyz="0.00111344591350004 -0.0046700515921087 -0.0851558711235764"
        rpy="0 0 0" />
      <mass
        value="314.639685314099" />
      <inertia
        ixx="0.0642922384062341"
        ixy="6.199380771973E-06"
        ixz="-4.8923498434973E-05"
        iyy="0.0338365568994341"
        iyz="-3.91580835767318E-05"
        izz="0.0387461795731439" />
    </inertial>
    <visual>
      <origin
        xyz="0 0 0"
        rpy="0 0 0" />
      <geometry>
        <mesh
          filename="../meshes/right_hand_yaw_link.STL" />
      </geometry>
      <material
        name="">
        <color
          rgba="0.752941176470588 0.752941176470588 0.752941176470588 1" />
      </material>
    </visual>
    <collision>
      <origin
        xyz="0 0 0"
        rpy="0 0 0" />
      <geometry>
        <mesh
          filename="../meshes/right_hand_yaw_link.STL" />
      </geometry>
    </collision>
  </link>
  <joint
    name="right_wrist_yaw_joint"
    type="revolute">
    <origin
      xyz="0 0 -0.05945"
      rpy="0 0 0" />
    <parent
      link="right_lower_arm_pitch_link" />
    <child
      link="right_hand_yaw_link" />
    <axis
      xyz="0 0 1" />
    <limit
      lower="-2.97"
      upper="2.97"
      effort="10.2"
      velocity="24.4" />
  </joint>
  <link
    name="right_hand_roll_link">
    <inertial>
      <origin
        xyz="-1.91911486702168E-08 0.000244128701142377 -1.08191427622417E-08"
        rpy="0 0 0" />
      <mass
        value="0.00525337141813315" />
      <inertia
        ixx="6.5747595661794E-08"
        ixy="-6.85771405909717E-13"
        ixz="2.20713600314006E-12"
        iyy="3.52512694086109E-07"
        iyz="1.46665980646826E-15"
        izz="3.52673983602149E-07" />
    </inertial>
    <visual>
      <origin
        xyz="0 0 0"
        rpy="0 0 0" />
      <geometry>
        <mesh
          filename="../meshes/right_hand_roll_link.STL" />
      </geometry>
      <material
        name="">
        <color
          rgba="0.752941176470588 0.752941176470588 0.752941176470588 1" />
      </material>
    </visual>
    <collision>
      <origin
        xyz="0 0 0"
        rpy="0 0 0" />
      <geometry>
        <mesh
          filename="../meshes/right_hand_roll_link.STL" />
      </geometry>
    </collision>
  </link>
  <joint
    name="right_wrist_roll_joint"
    type="revolute">
    <origin
      xyz="0 0 -0.19115"
      rpy="0 0 0" />
    <parent
      link="right_hand_yaw_link" />
    <child
      link="right_hand_roll_link" />
    <axis
      xyz="1 0 0" />
    <limit
      lower="-0.96"
      upper="0.87"
      effort="3.95"
      velocity="27.96" />
  </joint>
  <link
    name="right_hand_pitch_link">
    <inertial>
      <origin
        xyz="-4.79702122080372E-07 -0.00566605453217534 -0.00937684415464332"
        rpy="0 0 0" />
      <mass
        value="0.0499844124155361" />
      <inertia
        ixx="6.65779309889213E-06"
        ixy="6.99264224461709E-11"
        ixz="-2.13708320051604E-10"
        iyy="6.31126498386533E-06"
        iyz="4.31301511177247E-07"
        izz="8.67569843864194E-06" />
    </inertial>
    <visual>
      <origin
        xyz="0 0 0"
        rpy="0 0 0" />
      <geometry>
        <mesh
          filename="../meshes/right_hand_pitch_link.STL" />
      </geometry>
      <material
        name="">
        <color
          rgba="0.752941176470588 0.752941176470588 0.752941176470588 1" />
      </material>
    </visual>
    <collision>
      <origin
        xyz="0 0 0"
        rpy="0 0 0" />
      <geometry>
        <mesh
          filename="../meshes/right_hand_pitch_link.STL" />
      </geometry>
    </collision>
  </link>
  <joint
    name="right_wrist_pitch_joint"
    type="revolute">
    <origin
      xyz="0 0 0"
      rpy="0 0 0" />
    <parent
      link="right_hand_roll_link" />
    <child
      link="right_hand_pitch_link" />
    <axis
      xyz="0 1 0" />
    <limit
      lower="-0.61"
      upper="0.61"
      effort="3.95"
      velocity="27.96" />
  </joint>



  <link
    name="right_end_effector_link">
  </link>
  <joint
    name="right_end_effector_joint"
    type="fixed">
    <origin
      xyz="0 0 0"
      rpy="0 0 0" />
    <parent
      link="right_hand_pitch_link" />
    <child
      link="right_end_effector_link" />
  </joint>



  <link
    name="R_hand_base_link">
    <inertial>
      <origin
        xyz="-0.00046411 0.00916118 -0.04313895"
        rpy="0 0 0" />
      <mass
        value="0.306" />
      <inertia
        ixx="0.00030404"
        ixy="4.9E-07"
        ixz="-3E-08"
        iyy="0.00041091"
        iyz="1E-08"
        izz="0.00019509" />
    </inertial>
    <visual>
      <origin
        xyz="0 0 0"
        rpy="0 0 0" />
      <geometry>
        <mesh
          filename="../meshes/fourier_hand_6dof/R_hand_base_link.STL" />
      </geometry>
      <material
        name="">
        <color
          rgba="0.86667 0.86667 0.8902 1" />
      </material>
    </visual>
    <collision>
      <origin
        xyz="0 0 0"
        rpy="0 0 0" />
      <geometry>
        <mesh
          filename="../meshes/fourier_hand_6dof/R_hand_base_link.STL" />
      </geometry>
    </collision>
  </link>
  <joint
    name="R_hand_base_joint"
    type="fixed">
    <origin
      xyz="0 0 -0.0210000000049082"
      rpy="-6.83500415935726E-05 1.22100046026127E-05 0" />
    <parent
      link="right_end_effector_link" />
    <child
      link="R_hand_base_link" />
    <axis
      xyz="0 0 0" />
  </joint>
  <link
    name="R_thumb_proximal_base_link">
    <inertial>
      <origin
        xyz="0.01102125 -2.455E-05 -0.00077678"
        rpy="0 0 0" />
      <mass
        value="0.00948218" />
      <inertia
        ixx="3E-07"
        ixy="1E-08"
        ixz="4E-08"
        iyy="9.5E-07"
        iyz="1E-08"
        izz="9.7E-07" />
    </inertial>
    <visual>
      <origin
        xyz="0 0 0"
        rpy="0 0 0" />
      <geometry>
        <mesh
          filename="../meshes/fourier_hand_6dof/R_thumb_proximal_base_link.STL" />
      </geometry>
      <material
        name="">
        <color
          rgba="0.8902 0.8902 0.91373 1" />
      </material>
    </visual>
    <collision>
      <origin
        xyz="0 0 0"
        rpy="0 0 0" />
      <geometry>
        <mesh
          filename="../meshes/fourier_hand_6dof/R_thumb_proximal_base_link.STL" />
      </geometry>
    </collision>
  </link>
  <joint
    name="R_thumb_proximal_yaw_joint"
    type="revolute">
    <origin
      xyz="0.021995 0.015502 -0.024995"
      rpy="3.1416 0 0" />
    <parent
      link="R_hand_base_link" />
    <child
      link="R_thumb_proximal_base_link" />
    <axis
      xyz="0 0 1" />
    <limit
      lower="-1.74"
      upper="0"
      effort="10"
      velocity="0.8" />
  </joint>
  <link
    name="R_thumb_proximal_link">
    <inertial>
      <origin
        xyz="0.03218903 0.000287 -2.839E-05"
        rpy="0 0 0" />
      <mass
        value="0.07405243" />
      <inertia
        ixx="1.132E-05"
        ixy="-1.7E-07"
        ixz="4E-08"
        iyy="3.228E-05"
        iyz="-1E-08"
        izz="3.419E-05" />
    </inertial>
    <visual>
      <origin
        xyz="0 0 0"
        rpy="0 0 0" />
      <geometry>
        <mesh
          filename="../meshes/fourier_hand_6dof/R_thumb_proximal_link.STL" />
      </geometry>
      <material
        name="">
        <color
          rgba="0.86667 0.86667 0.8902 1" />
      </material>
    </visual>
    <collision>
      <origin
        xyz="0 0 0"
        rpy="0 0 0" />
      <geometry>
        <mesh
          filename="../meshes/fourier_hand_6dof/R_thumb_proximal_link.STL" />
      </geometry>
    </collision>
  </link>
  <joint
    name="R_thumb_proximal_pitch_joint"
    type="revolute">
    <origin
      xyz="0.02175 0 0"
      rpy="1.5709 1.221E-05 0" />
    <parent
      link="R_thumb_proximal_base_link" />
    <child
      link="R_thumb_proximal_link" />
    <axis
      xyz="0 0 1" />
    <limit
      lower="0"
      upper="1.22"
      effort="10"
      velocity="0.8" />
  </joint>
  <link
    name="R_thumb_distal_link">
    <inertial>
      <origin
        xyz="0.01373199 -0.00277415 0"
        rpy="0 0 0" />
      <mass
        value="0.01974135" />
      <inertia
        ixx="9E-07"
        ixy="-9E-08"
        ixz="0"
        iyy="2.33E-06"
        iyz="0"
        izz="2.19E-06" />
    </inertial>
    <visual>
      <origin
        xyz="0 0 0"
        rpy="0 0 0" />
      <geometry>
        <mesh
          filename="../meshes/fourier_hand_6dof/R_thumb_distal_link.STL" />
      </geometry>
      <material
        name="">
        <color
          rgba="0.86667 0.86667 0.8902 1" />
      </material>
    </visual>
    <collision>
      <origin
        xyz="0 0 0"
        rpy="0 0 0" />
      <geometry>
        <mesh
          filename="../meshes/fourier_hand_6dof/R_thumb_distal_link.STL" />
      </geometry>
    </collision>
  </link>
  <joint
    name="R_thumb_distal_joint"
    type="revolute">
    <origin
      xyz="0.061444 0.0082822 0"
      rpy="0 0 1.221E-05" />
    <parent
      link="R_thumb_proximal_link" />
    <child
      link="R_thumb_distal_link" />
    <axis
      xyz="0 0 1" />
    <limit
      lower="0"
      upper="1.23"
      effort="10"
      velocity="0.8" />
    <mimic
      joint="R_thumb_proximal_pitch_joint"
      multiplier="0.974"
      offset="0" />
  </joint>

  <link name="R_thumb_tip_link">
    <visual>
      <origin
        xyz="0 0 0"
        rpy="0 0 0" />
      <geometry>
        <sphere radius="0.005" />
      </geometry>
      <material name="yellow">
        <color rgba="0.9 1 0 1" />
      </material>
    </visual>
  </link>
  <joint name="R_thumb_tip_joint" type="fixed">
    <parent link="R_thumb_distal_link" />
    <child link="R_thumb_tip_link" />
    <origin rpy="0 0 0" xyz="0.031 0 0" />
  </joint>


  <link
    name="R_index_proximal_link">
    <inertial>
      <origin
        xyz="0.00959983 0.0004431 2.96E-06"
        rpy="0 0 0" />
      <mass
        value="0.01911771" />
      <inertia
        ixx="8.6E-07"
        ixy="1.2E-07"
        ixz="0"
        iyy="3.71E-06"
        iyz="0"
        izz="3.85E-06" />
    </inertial>
    <visual>
      <origin
        xyz="0 0 0"
        rpy="0 0 0" />
      <geometry>
        <mesh
          filename="../meshes/fourier_hand_6dof/R_index_proximal_link.STL" />
      </geometry>
      <material
        name="">
        <color
          rgba="0.8902 0.8902 0.91373 1" />
      </material>
    </visual>
    <collision>
      <origin
        xyz="0 0 0"
        rpy="0 0 0" />
      <geometry>
        <mesh
          filename="../meshes/fourier_hand_6dof/R_index_proximal_link.STL" />
      </geometry>
    </collision>
  </link>
  <joint
    name="R_index_proximal_joint"
    type="revolute">
    <origin
      xyz="0.026864 0.012307 -0.095892"
      rpy="-3.1403 1.5184 0.0013039" />
    <parent
      link="R_hand_base_link" />
    <child
      link="R_index_proximal_link" />
    <axis
      xyz="0 0 1" />
    <limit
      lower="-1.57"
      upper="0"
      effort="10"
      velocity="0.8" />
  </joint>
  <link
    name="R_index_intermediate_link">
    <inertial>
      <origin
        xyz="0.01800441 0.00299919 -9.23E-06"
        rpy="0 0 0" />
      <mass
        value="0.01292544" />
      <inertia
        ixx="3.7E-07"
        ixy="2.5E-07"
        ixz="0"
        iyy="2.01E-06"
        iyz="0"
        izz="2.04E-06" />
    </inertial>
    <visual>
      <origin
        xyz="0 0 0"
        rpy="0 0 0" />
      <geometry>
        <mesh
          filename="../meshes/fourier_hand_6dof/R_index_intermediate_link.STL" />
      </geometry>
      <material
        name="">
        <color
          rgba="0.79216 0.81961 0.93333 1" />
      </material>
    </visual>
    <collision>
      <origin
        xyz="0 0 0"
        rpy="0 0 0" />
      <geometry>
        <mesh
          filename="../meshes/fourier_hand_6dof/R_index_intermediate_link.STL" />
      </geometry>
    </collision>
  </link>
  <joint
    name="R_index_intermediate_joint"
    type="revolute">
    <origin
      xyz="0.031532 -0.0054551 0"
      rpy="0 0 0" />
    <parent
      link="R_index_proximal_link" />
    <child
      link="R_index_intermediate_link" />
    <axis
      xyz="0 0 1" />
    <limit
      lower="-1.74"
      upper="0"
      effort="10"
      velocity="0.8" />
    <mimic
      joint="R_index_proximal_joint"
      multiplier="1.128"
      offset="0" />
  </joint>

  <link name="R_index_tip_link">
    <visual>
      <origin
        xyz="0 0 0"
        rpy="0 0 0" />
      <geometry>
        <sphere radius="0.005" />
      </geometry>
      <material name="yellow">
        <color rgba="0.9 1 0 1" />
      </material>
    </visual>
  </link>
  <joint name="R_index_tip_joint" type="fixed">
    <parent link="R_index_intermediate_link" />
    <child link="R_index_tip_link" />
    <origin rpy="0 0 0" xyz="0.038 -0.0015 0" />
  </joint>


  <link
    name="R_middle_proximal_link">
    <inertial>
      <origin
        xyz="0.00955708 0.00071862 2.96E-06"
        rpy="0 0 0" />
      <mass
        value="0.01911771" />
      <inertia
        ixx="8.6E-07"
        ixy="6E-08"
        ixz="0"
        iyy="3.72E-06"
        iyz="0"
        izz="3.85E-06" />
    </inertial>
    <visual>
      <origin
        xyz="0 0 0"
        rpy="0 0 0" />
      <geometry>
        <mesh
          filename="../meshes/fourier_hand_6dof/R_middle_proximal_link.STL" />
      </geometry>
      <material
        name="">
        <color
          rgba="0.8902 0.8902 0.91373 1" />
      </material>
    </visual>
    <collision>
      <origin
        xyz="0 0 0"
        rpy="0 0 0" />
      <geometry>
        <mesh
          filename="../meshes/fourier_hand_6dof/R_middle_proximal_link.STL" />
      </geometry>
    </collision>
  </link>
  <joint
    name="R_middle_proximal_joint"
    type="revolute">
    <origin
      xyz="0.0084962 0.012307 -0.097896"
      rpy="-1.7476 1.5707 1.394" />
    <parent
      link="R_hand_base_link" />
    <child
      link="R_middle_proximal_link" />
    <axis
      xyz="0 0 1" />
    <limit
      lower="-1.57"
      upper="0"
      effort="10"
      velocity="0.8" />
  </joint>
  <link
    name="R_middle_intermediate_link">
    <inertial>
      <origin
        xyz="0.02128 0.0040831 -9.98E-06"
        rpy="0 0 0" />
      <mass
        value="0.01535" />
      <inertia
        ixx="4.1E-07"
        ixy="2.2E-07"
        ixz="0"
        iyy="3.28E-06"
        iyz="0"
        izz="3.29E-06" />
    </inertial>
    <visual>
      <origin
        xyz="0 0 0"
        rpy="0 0 0" />
      <geometry>
        <mesh
          filename="../meshes/fourier_hand_6dof/R_middle_intermediate_link.STL" />
      </geometry>
      <material
        name="">
        <color
          rgba="0.86667 0.86667 0.8902 1" />
      </material>
    </visual>
    <collision>
      <origin
        xyz="0 0 0"
        rpy="0 0 0" />
      <geometry>
        <mesh
          filename="../meshes/fourier_hand_6dof/R_middle_intermediate_link.STL" />
      </geometry>
    </collision>
  </link>
  <joint
    name="R_middle_intermediate_joint"
    type="revolute">
    <origin
      xyz="0.031662 -0.0046408 0"
      rpy="0 0 0" />
    <parent
      link="R_middle_proximal_link" />
    <child
      link="R_middle_intermediate_link" />
    <axis
      xyz="0 0 1" />
    <limit
      lower="-1.74"
      upper="0"
      effort="10"
      velocity="0.8" />
    <mimic
      joint="R_middle_proximal_joint"
      multiplier="1.131"
      offset="0" />
  </joint>

  <link name="R_middle_tip_link">
    <visual>
      <origin
        xyz="0 0 0"
        rpy="0 0 0" />
      <geometry>
        <sphere radius="0.005" />
      </geometry>
      <material name="yellow">
        <color rgba="0.9 1 0 1" />
      </material>
    </visual>
  </link>
  <joint name="R_middle_tip_joint" type="fixed">
    <parent link="R_middle_intermediate_link" />
    <child link="R_middle_tip_link" />
    <origin rpy="0 0 0" xyz="0.045 0.0005 0" />
  </joint>


  <link
    name="R_ring_proximal_link">
    <inertial>
      <origin
        xyz="0.00959986 0.00044244 2.96E-06"
        rpy="0 0 0" />
      <mass
        value="0.01911771" />
      <inertia
        ixx="8.6E-07"
        ixy="1.2E-07"
        ixz="0"
        iyy="3.71E-06"
        iyz="0"
        izz="3.85E-06" />
    </inertial>
    <visual>
      <origin
        xyz="0 0 0"
        rpy="0 0 0" />
      <geometry>
        <mesh
          filename="../meshes/fourier_hand_6dof/R_ring_proximal_link.STL" />
      </geometry>
      <material
        name="">
        <color
          rgba="0.8902 0.8902 0.91373 1" />
      </material>
    </visual>
    <collision>
      <origin
        xyz="0 0 0"
        rpy="0 0 0" />
      <geometry>
        <mesh
          filename="../meshes/fourier_hand_6dof/R_ring_proximal_link.STL" />
      </geometry>
    </collision>
  </link>
  <joint
    name="R_ring_proximal_joint"
    type="revolute">
    <origin
      xyz="-0.009965 0.012307 -0.097841"
      rpy="0 1.5184 3.1416" />
    <parent
      link="R_hand_base_link" />
    <child
      link="R_ring_proximal_link" />
    <axis
      xyz="0 0 1" />
    <limit
      lower="-1.57"
      upper="0"
      effort="10"
      velocity="0.8" />
  </joint>
  <link
    name="R_ring_intermediate_link">
    <inertial>
      <origin
        xyz="0.018005 0.002998 -9.23E-06"
        rpy="0 0 0" />
      <mass
        value="0.012925" />
      <inertia
        ixx="3.7E-07"
        ixy="2.5E-07"
        ixz="0"
        iyy="2.01E-06"
        iyz="0"
        izz="2.04E-06" />
    </inertial>
    <visual>
      <origin
        xyz="0 0 0"
        rpy="0 0 0" />
      <geometry>
        <mesh
          filename="../meshes/fourier_hand_6dof/R_ring_intermediate_link.STL" />
      </geometry>
      <material
        name="">
        <color
          rgba="0.29804 0.29804 0.29804 1" />
      </material>
    </visual>
    <collision>
      <origin
        xyz="0 0 0"
        rpy="0 0 0" />
      <geometry>
        <mesh
          filename="../meshes/fourier_hand_6dof/R_ring_intermediate_link.STL" />
      </geometry>
    </collision>
  </link>
  <joint
    name="R_ring_intermediate_joint"
    type="revolute">
    <origin
      xyz="0.031531 -0.0054572 0"
      rpy="0 0 0" />
    <parent
      link="R_ring_proximal_link" />
    <child
      link="R_ring_intermediate_link" />
    <axis
      xyz="0 0 1" />
    <limit
      lower="-1.74"
      upper="0"
      effort="10"
      velocity="0.8" />
    <mimic
      joint="R_ring_proximal_joint"
      multiplier="1.143"
      offset="0" />
  </joint>

  <link name="R_ring_tip_link">
    <visual>
      <origin
        xyz="0 0 0"
        rpy="0 0 0" />
      <geometry>
        <sphere radius="0.005" />
      </geometry>
      <material name="green">
        <color rgba="0.9 1 0 1" />
      </material>
    </visual>
  </link>
  <joint name="R_ring_tip_joint" type="fixed">
    <parent link="R_ring_intermediate_link" />
    <child link="R_ring_tip_link" />
    <origin rpy="0 0 0" xyz="0.038 -0.0015 0" />
  </joint>


  <link
    name="R_pinky_proximal_link">
    <inertial>
      <origin
        xyz="0.00964414 9.378E-05 2.96E-06"
        rpy="0 0 0" />
      <mass
        value="0.01911771" />
      <inertia
        ixx="8.8E-07"
        ixy="2E-07"
        ixz="0"
        iyy="3.7E-06"
        iyz="0"
        izz="3.85E-06" />
    </inertial>
    <visual>
      <origin
        xyz="0 0 0"
        rpy="0 0 0" />
      <geometry>
        <mesh
          filename="../meshes/fourier_hand_6dof/R_pinky_proximal_link.STL" />
      </geometry>
      <material
        name="">
        <color
          rgba="0.8902 0.8902 0.91373 1" />
      </material>
    </visual>
    <collision>
      <origin
        xyz="0 0 0"
        rpy="0 0 0" />
      <geometry>
        <mesh
          filename="../meshes/fourier_hand_6dof/R_pinky_proximal_link.STL" />
      </geometry>
    </collision>
  </link>
  <joint
    name="R_pinky_proximal_joint"
    type="revolute">
    <origin
      xyz="-0.028232 0.012307 -0.095916"
      rpy="-0.00065397 1.4661 3.1409" />
    <parent
      link="R_hand_base_link" />
    <child
      link="R_pinky_proximal_link" />
    <axis
      xyz="0 0 1" />
    <limit
      lower="-1.57"
      upper="0"
      effort="10"
      velocity="0.8" />
  </joint>
  <link
    name="R_pinky_intermediate_link">
    <inertial>
      <origin
        xyz="0.0160962 0.00118598 -8.72E-06"
        rpy="0 0 0" />
      <mass
        value="0.00568707" />
      <inertia
        ixx="1.7E-07"
        ixy="1.3E-07"
        ixz="0"
        iyy="6.2E-07"
        iyz="0"
        izz="6.7E-07" />
    </inertial>
    <visual>
      <origin
        xyz="0 0 0"
        rpy="0 0 0" />
      <geometry>
        <mesh
          filename="../meshes/fourier_hand_6dof/R_pinky_intermediate_link.STL" />
      </geometry>
      <material
        name="">
        <color
          rgba="0.79216 0.81961 0.93333 1" />
      </material>
    </visual>
    <collision>
      <origin
        xyz="0 0 0"
        rpy="0 0 0" />
      <geometry>
        <mesh
          filename="../meshes/fourier_hand_6dof/R_pinky_intermediate_link.STL" />
      </geometry>
    </collision>
  </link>
  <joint
    name="R_pinky_intermediate_joint"
    type="revolute">
    <origin
      xyz="0.031338 -0.0064763 0"
      rpy="0 0 6.7976E-05" />
    <parent
      link="R_pinky_proximal_link" />
    <child
      link="R_pinky_intermediate_link" />
    <axis
      xyz="0 0 1" />
    <limit
      lower="-1.74"
      upper="0"
      effort="10"
      velocity="0.8" />
    <mimic
      joint="R_pinky_proximal_joint"
      multiplier="1.129"
      offset="0" />
  </joint>

  <link name="R_pinky_tip_link">
    <visual>
      <origin
        xyz="0 0 0"
        rpy="0 0 0" />
      <geometry>
        <sphere radius="0.005" />
      </geometry>
      <material name="yellow">
        <color rgba="0.9 1 0 1" />
      </material>
    </visual>
  </link>
  <joint name="R_pinky_tip_joint" type="fixed">
    <parent link="R_pinky_intermediate_link" />
    <child link="R_pinky_tip_link" />
    <origin rpy="0 0 0" xyz="0.031 -0.004 0" />
  </joint>



  <link
    name="head_roll_link">
    <inertial>
      <origin
        xyz="0.00424993779842264 -1.03396088357854E-08 7.56203899499042E-09"
        rpy="0 0 0" />
      <mass
        value="0.00788031826759117" />
      <inertia
        ixx="4.34011506346405E-07"
        ixy="-4.95969262194408E-13"
        ixz="2.47248045034325E-13"
        iyy="1.55693275152624E-07"
        iyz="2.22833161250769E-12"
        izz="4.427024203186E-07" />
    </inertial>
    <visual>
      <origin
        xyz="0 0 0"
        rpy="0 0 0" />
      <geometry>
        <mesh
          filename="../meshes/head_roll_link.STL" />
      </geometry>
      <material
        name="">
        <color
          rgba="0.752941176470588 0.752941176470588 0.752941176470588 1" />
      </material>
    </visual>
    <collision>
      <origin
        xyz="0 0 0"
        rpy="0 0 0" />
      <geometry>
        <mesh
          filename="../meshes/head_roll_link.STL" />
      </geometry>
    </collision>
  </link>
  <joint
    name="head_roll_joint"
    type="revolute">
    <origin
      xyz="0.002 0.0005184 0.14465"
      rpy="0 0 0" />
    <parent
      link="torso_link" />
    <child
      link="head_roll_link" />
    <axis
      xyz="1 0 0" />
    <limit
      lower="-0.35"
      upper="0.35"
      effort="3.95"
      velocity="27.96" />
  </joint>
  <link
    name="head_pitch_link">
    <inertial>
      <origin
        xyz="-0.00217650705476857 -3.73982365187153E-07 0.0175093650421931"
        rpy="0 0 0" />
      <mass
        value="0.0633607310944292" />
      <inertia
        ixx="8.3483844042092E-06"
        ixy="8.43773799466634E-11"
        ixz="-3.98067198262649E-07"
        iyy="1.01810057124236E-05"
        iyz="2.24751267038447E-10"
        izz="1.38206834143736E-05" />
    </inertial>
    <visual>
      <origin
        xyz="0 0 0"
        rpy="0 0 0" />
      <geometry>
        <mesh
          filename="../meshes/head_pitch_link.STL" />
      </geometry>
      <material
        name="">
        <color
          rgba="0.752941176470588 0.752941176470588 0.752941176470588 1" />
      </material>
    </visual>
    <collision>
      <origin
        xyz="0 0 0"
        rpy="0 0 0" />
      <geometry>
        <mesh
          filename="../meshes/head_pitch_link.STL" />
      </geometry>
    </collision>
  </link>
  <joint
    name="head_pitch_joint"
    type="revolute">
    <origin
      xyz="0 0 0"
      rpy="0 0 0" />
    <parent
      link="head_roll_link" />
    <child
      link="head_pitch_link" />
    <axis
      xyz="0 1 0" />
    <limit
      lower="-0.87"
      upper="0.87"
      effort="3.95"
      velocity="27.96" />
  </joint>
  <link
    name="head_yaw_link">
    <inertial>
      <origin
        xyz="-0.00158659211035067 6.88926717782173E-05 0.00203950965596933"
        rpy="0 0 0" />
      <mass
        value="157.468052909819" />
      <inertia
        ixx="0.0173136754699814"
        ixy="-4.1313011955636E-05"
        ixz="-0.000234426408975796"
        iyy="0.0201300302455"
        iyz="2.89801645745342E-05"
        izz="0.0326483821046668" />
    </inertial>
    <visual>
      <origin
        xyz="0 0 0"
        rpy="0 0 0" />
      <geometry>
        <mesh
          filename="../meshes/remove_head/head_yaw_link.STL" />
      </geometry>
      <material
        name="">
        <color
          rgba="0.752941176470588 0.752941176470588 0.752941176470588 1" />
      </material>
    </visual>
    <collision>
      <origin
        xyz="0 0 0"
        rpy="0 0 0" />
      <geometry>
        <mesh
          filename="../meshes/remove_head/head_yaw_link.STL" />
      </geometry>
    </collision>
  </link>
  <joint
    name="head_yaw_joint"
    type="revolute">
    <origin
      xyz="0 0 0.0513"
      rpy="0 0 0" />
    <parent
      link="head_pitch_link" />
    <child
      link="head_yaw_link" />
    <axis
      xyz="0 0 1" />
    <limit
      lower="-2.71"
      upper="2.71"
      effort="3.95"
      velocity="27.96" />
  </joint>
  <link
    name="head_camera_link">
    <inertial>
      <origin
        xyz="-0.047758157520158 0.000122943489569663 -0.0378886136634861"
        rpy="0 0 0" />
      <mass
        value="0.200829633333977" />
      <inertia
        ixx="0.000198724274689514"
        ixy="-5.19577108562238E-07"
        ixz="1.0342960227418E-05"
        iyy="8.93130981684661E-05"
        iyz="2.84535231428988E-07"
        izz="0.000165689397580066" />
    </inertial>
    <visual>
      <origin
        xyz="0 0 0"
        rpy="0 0 0" />
      <geometry>
        <mesh
          filename="../meshes/remove_head/head_camera_link.STL" />
      </geometry>
      <material
        name="">
        <color
          rgba="0.752941176470588 0.752941176470588 0.752941176470588 1" />
      </material>
    </visual>
    <collision>
      <origin
        xyz="0 0 0"
        rpy="0 0 0" />
      <geometry>
        <mesh
          filename="../meshes/remove_head/head_camera_link.STL" />
      </geometry>
    </collision>
  </link>
  <joint
    name="head_camera_joint"
    type="fixed">
    <origin
      xyz="0.10587 0 0.12751"
      rpy="0 0.5236 0" />
    <parent
      link="head_yaw_link" />
    <child
      link="head_camera_link" />
    <axis
      xyz="0 0 0" />
  </joint>
  <link
    name="imu_link">
    <inertial>
      <origin
        xyz="-0.0621333069184308 -1.51291212126259E-06 -0.00312643332972155"
        rpy="0 0 0" />
      <mass
        value="0.0505078149734707" />
      <inertia
        ixx="8.37757787881593E-06"
        ixy="4.68136168189613E-11"
        ixz="6.81854523821097E-08"
        iyy="8.81682660921222E-06"
        iyz="5.24506541459484E-12"
        izz="1.48136575639238E-05" />
    </inertial>
    <visual>
      <origin
        xyz="0 0 0"
        rpy="0 0 0" />
      <geometry>
        <mesh
          filename="../meshes/imu_link.STL" />
      </geometry>
      <material
        name="">
        <color
          rgba="0.752941176470588 0.752941176470588 0.752941176470588 1" />
      </material>
    </visual>
    <collision>
      <origin
        xyz="0 0 0"
        rpy="0 0 0" />
      <geometry>
        <mesh
          filename="../meshes/imu_link.STL" />
      </geometry>
    </collision>
  </link>
  <joint
    name="imu_joint"
    type="fixed">
    <origin
      xyz="0 0 -0.0596"
      rpy="0 0 0" />
    <parent
      link="base_link" />
    <child
      link="imu_link" />
    <axis
      xyz="0 0 0" />
  </joint>
</robot>